File: Latex/Final_thesis_document/Raw_Data/DSC/DSC_Alberto/Microspheres/ExpDat_PHBH_microspheres-second heating.txt
#EXPORTTYPE:DATA SINGLE
#FILE:PHBH_microspheres.ngb-sdg
#FORMAT:NETZSCH5
#FTYPE:ASCII
#IDENTITY:PHBH
#DECIMAL:POINT
#SEPARATOR:SEMICOLON
#MTYPE:DSC
#INSTRUMENT:NETZSCH DSC 214
#PROJECT:
#DATE/TIME:24.09.2021 10:05
#CORR. FILE:
#TEMPCAL:applied
#SENSITIVITY:applied
#LABORATORY:
#OPERATOR:Alberto
#REMARK:
#SAMPLE:PHBH_microspheres
#SAMPLE MASS /mg:8
#MATERIAL:
#REFERENCE:vuoto
#REFERENCE MASS /mg:0
#TYPE OF CRUCIBLE:Concavus Pan Al, pierced lid
#SAMPLE CRUCIBLE MASS /mg:0
#REFERENCE CRUCIBLE MASS /mg:0
#M.RANGE /‘V:5000
#TAU-R:applied
#CORR. CODE:050
#EXO:+1
#RANGE:-30›C/10,0(K/min)/180›C
#SEGMENT:S5/5
#SEG. 5:-30›C/10,0(K/min)/180›C

##Temp./›C;Time/min;DSC/(mW/mg);Sensit./(uV/mW)
-29.83566;42.50500;-1.441530e-002;3.39901
-28.83566;42.68368;      -0.23688;3.40080
-27.83566;42.75854;      -0.23170;3.40257
-26.83566;42.82543;      -0.22252;3.40432
-25.83566;42.89700;      -0.21383;3.40605
-24.83566;42.98377;      -0.20773;3.40776
-23.83566;43.09400;      -0.19685;3.40945
-22.83566;43.21131;      -0.19737;3.41112
-21.83566;43.31706;      -0.20693;3.41276
-20.83566;43.41475;      -0.21350;3.41439
-19.83566;43.51043;      -0.21470;3.41599
-18.83566;43.60779;      -0.21248;3.41758
-17.83566;43.70793;      -0.21018;3.41914
-16.83566;43.80969;      -0.20949;3.42068
-15.83566;43.91123;      -0.21073;3.42220
-14.83566;44.01167;      -0.21275;3.42370
-13.83566;44.11118;      -0.21385;3.42518
-12.83566;44.21054;      -0.21411;3.42663
-11.83566;44.31046;      -0.21410;3.42807
-10.83566;44.41095;      -0.21482;3.42949
 -9.83566;44.51134;      -0.21637;3.43088
 -8.83566;44.61107;      -0.21768;3.43226
 -7.83566;44.71082;      -0.21872;3.43361
 -6.83566;44.81106;      -0.22023;3.43494
 -5.83566;44.91151;      -0.22293;3.43625
 -4.83566;45.01178;      -0.22698;3.43754
 -3.83566;45.11174;      -0.23176;3.43881
 -2.83566;45.21173;      -0.23713;3.44006
 -1.83566;45.31247;      -0.24348;3.44129
 -0.83566;45.41380;      -0.25923;3.44250
  0.16434;45.51461;      -0.27770;3.44369
  1.16434;45.61511;      -0.30257;3.44485
  2.16434;45.71579;      -0.31601;3.44600
  3.16434;45.81657;      -0.30898;3.44712
  4.16434;45.91681;      -0.30038;3.44823
  5.16434;46.01636;      -0.29854;3.44931
  6.16434;46.11565;      -0.29728;3.45037
  7.16434;46.21536;      -0.29565;3.45142
  8.16434;46.31573;      -0.29473;3.45244
  9.16434;46.41628;      -0.29534;3.45344
 10.16434;46.51623;      -0.29651;3.45442
 11.16434;46.61576;      -0.29646;3.45538
 12.16434;46.71548;      -0.29602;3.45632
 13.16434;46.81560;      -0.29557;3.45724
 14.16434;46.91599;      -0.29564;3.45814
 15.16434;47.01626;      -0.29641;3.45902
 16.16434;47.11613;      -0.29674;3.45987
 17.16434;47.21585;      -0.29618;3.46071
 18.16434;47.31590;      -0.29522;3.46153
 19.16434;47.41628;      -0.29491;3.46232
 20.16434;47.51657;      -0.29524;3.46310
 21.16434;47.61629;      -0.29511;3.46385
 22.16434;47.71573;      -0.29372;3.46459
 23.16434;47.81554;      -0.29145;3.46531
 24.16434;47.91584;      -0.28947;3.46600
 25.16434;48.01626;      -0.28836;3.46668
 26.16434;48.11609;      -0.28725;3.46733
 27.16434;48.21554;      -0.28461;3.46796
 28.16434;48.31529;      -0.28108;3.46858
 29.16434;48.41544;      -0.27770;3.46917
 30.16434;48.51559;      -0.27522;3.46975
 31.16434;48.61530;      -0.27302;3.47030
 32.16434;48.71461;      -0.26929;3.47084
 33.16434;48.81425;      -0.26372;3.47135
 34.16434;48.91438;      -0.25787;3.47184
 35.16434;49.01462;      -0.25192;3.47232
 36.16434;49.11443;      -0.24631;3.47277
 37.16434;49.21367;      -0.24001;3.47321
 38.16434;49.31286;      -0.23036;3.47362
 39.16434;49.41232;      -0.21861;3.47402
 40.16434;49.51208;      -0.20487;3.47439
 41.16434;49.61184;      -0.18990;3.47475
 42.16434;49.71113;      -0.17623;3.47508
 43.16434;49.80985;      -0.15753;3.47540
 44.16434;49.90836;      -0.13506;3.47570
 45.16434;50.00700;      -0.10884;3.47598
 46.16434;50.10586;-7.992444e-002;3.47623
 47.16434;50.20449;-5.357581e-002;3.47647
 48.16434;50.30273;-3.269665e-002;3.47669
 49.16434;50.40136;-1.793713e-002;3.47689
 50.16434;50.50118;-1.843028e-002;3.47707
 51.16434;50.60222;-3.758643e-002;3.47723
 52.16434;50.70397;-7.458399e-002;3.47737
 53.16434;50.80584;      -0.11912;3.47749
 54.16434;50.90783;      -0.16230;3.47760
 55.16434;51.00999;      -0.19858;3.47768
 56.16434;51.11202;      -0.22561;3.47774
 57.16434;51.21364;      -0.24363;3.47779
 58.16434;51.31450;      -0.25864;3.47782
 59.16434;51.41454;      -0.26897;3.47782
 60.16434;51.51459;      -0.27395;3.47781
 61.16434;51.61511;      -0.27717;3.47778
 62.16434;51.71587;      -0.28102;3.47773
 63.16434;51.81630;      -0.28567;3.47766
 64.16434;51.91617;      -0.28915;3.47758
 65.16434;52.01587;      -0.29144;3.47747
 66.16434;52.11601;      -0.29323;3.47735
 67.16434;52.21650;      -0.29530;3.47720
 68.16434;52.31705;      -0.29865;3.47704
 69.16434;52.41705;      -0.30233;3.47686
 70.16434;52.51657;      -0.30452;3.47666
 71.16434;52.61633;      -0.30582;3.47645
 72.16434;52.71683;      -0.30749;3.47621
 73.16434;52.81767;      -0.31062;3.47596
 74.16434;52.91815;      -0.31507;3.47568
 75.16434;53.01784;      -0.31880;3.47539
 76.16434;53.11731;      -0.32101;3.47508
 77.16434;53.21740;      -0.32266;3.47476
 78.16434;53.31812;      -0.32527;3.47441
 79.16434;53.41886;      -0.32982;3.47405
 80.16434;53.51893;      -0.33461;3.47367
 81.16434;53.61848;      -0.33793;3.47327
 82.16434;53.71841;      -0.34044;3.47285
 83.16434;53.81888;      -0.34334;3.47242
 84.16434;53.91961;      -0.34731;3.47196
 85.16434;54.02007;      -0.35261;3.47149
 86.16434;54.11988;      -0.35758;3.47100
 87.16434;54.21942;      -0.36102;3.47050
 88.16434;54.31940;      -0.36333;3.46997
 89.16434;54.41990;      -0.36558;3.46943
 90.16434;54.52066;      -0.36904;3.46887
 91.16434;54.62109;      -0.37312;3.46830
 92.16434;54.72101;      -0.37623;3.46770
 93.16434;54.82090;      -0.37873;3.46709
 94.16434;54.92103;      -0.38132;3.46647
 95.16434;55.02143;      -0.38460;3.46582
 96.16434;55.12194;      -0.39003;3.46516
 97.16434;55.22209;      -0.39660;3.46448
 98.16434;55.32194;      -0.40220;3.46378
 99.16434;55.42198;      -0.40709;3.46307
100.16434;55.52244;      -0.41184;3.46234
101.16434;55.62331;      -0.41721;3.46159
102.16434;55.72408;      -0.42659;3.46082
103.16434;55.82434;      -0.44001;3.46004
104.16434;55.92452;      -0.45340;3.45924
105.16434;56.02519;      -0.46600;3.45843
106.16434;56.12625;      -0.47857;3.45760
107.16434;56.22731;      -0.48789;3.45675
108.16434;56.32756;      -0.48929;3.45589
109.16434;56.42675;      -0.47691;3.45500
110.16434;56.52527;      -0.44887;3.45411
111.16434;56.62389;      -0.42305;3.45319
112.16434;56.72326;      -0.40858;3.45226
113.16434;56.82345;      -0.40645;3.45132
114.16434;56.92366;      -0.41924;3.45036
115.16434;57.02380;      -0.43997;3.44938
116.16434;57.12432;      -0.45851;3.44838
117.16434;57.22549;      -0.47708;3.44737
118.16434;57.32720;      -0.49927;3.44635
119.16434;57.42888;      -0.52281;3.44530
120.16434;57.52989;      -0.55199;3.44425
121.16434;57.63063;      -0.57812;3.44317
122.16434;57.73179;      -0.59521;3.44208
123.16434;57.83314;      -0.60731;3.44098
124.16434;57.93450;      -0.62117;3.43986
125.16434;58.03547;      -0.63322;3.43872
126.16434;58.13565;      -0.64569;3.43757
127.16434;58.23545;      -0.65185;3.43640
128.16434;58.33517;      -0.64359;3.43522
129.16434;58.43474;      -0.62576;3.43403
130.16434;58.53421;      -0.60152;3.43281
131.16434;58.63324;      -0.57007;3.43159
132.16434;58.73136;      -0.54059;3.43034
133.16434;58.82889;      -0.50742;3.42909
134.16434;58.92668;      -0.46804;3.42781
135.16434;59.02500;      -0.43006;3.42653
136.16434;59.12383;      -0.40057;3.42522
137.16434;59.22282;      -0.38039;3.42391
138.16434;59.32159;      -0.37048;3.42258
139.16434;59.42040;      -0.36164;3.42123
140.16434;59.51987;      -0.35470;3.41987
141.16434;59.61993;      -0.35017;3.41850
142.16434;59.72049;      -0.34809;3.41711
143.16434;59.82085;      -0.34999;3.41570
144.16434;59.92028;      -0.35253;3.41429
145.16434;60.01920;      -0.35196;3.41285
146.16434;60.11876;      -0.34998;3.41141
147.16434;60.21923;      -0.34836;3.40995
148.16434;60.32029;      -0.34865;3.40847
149.16434;60.42093;      -0.35149;3.40699
150.16434;60.52059;      -0.35349;3.40548
151.16434;60.61970;      -0.35302;3.40397
152.16434;60.71932;      -0.35169;3.40244
153.16434;60.81969;      -0.35092;3.40089
154.16434;60.92038;      -0.35118;3.39934
155.16434;61.02079;      -0.35314;3.39777
156.16434;61.12050;      -0.35476;3.39618
157.16434;61.21990;      -0.35464;3.39459
158.16434;61.31964;      -0.35383;3.39298
159.16434;61.41989;      -0.35303;3.39135
160.16434;61.52060;      -0.35320;3.38972
161.16434;61.62115;      -0.35546;3.38807
162.16434;61.72085;      -0.35752;3.38640
163.16434;61.81996;      -0.35744;3.38473
164.16434;61.91945;      -0.35620;3.38304
165.16434;62.01965;      -0.35482;3.38133
166.16434;62.12041;      -0.35409;3.37962
167.16434;62.22124;      -0.35613;3.37789
168.16434;62.32130;      -0.35861;3.37615
169.16434;62.42062;      -0.35910;3.37440
170.16434;62.51997;      -0.35947;3.37263
171.16434;62.61957;      -0.35846;3.37086
172.16434;62.71977;      -0.35597;3.36907
173.16434;62.82087;      -0.35653;3.36726
174.16434;62.92165;      -0.35971;3.36545
175.16434;63.02121;      -0.36149;3.36362
176.16434;63.12038;      -0.36059;3.36178
177.16434;63.22014;      -0.35874;3.35993
178.16434;63.32070;      -0.35768;3.35807
179.16434;63.42150;      -0.35859;3.35619