File: Latex/Final_thesis_document/Raw_Data/DSC/DSC_Alberto/Microspheres/ExpDat_PHBH_microspheres-first heating.txt
#EXPORTTYPE:DATA SINGLE
#FILE:PHBH_microspheres.ngb-sdg
#FORMAT:NETZSCH5
#FTYPE:ASCII
#IDENTITY:PHBH
#DECIMAL:POINT
#SEPARATOR:SEMICOLON
#MTYPE:DSC
#INSTRUMENT:NETZSCH DSC 214
#PROJECT:
#DATE/TIME:24.09.2021 10:05
#CORR. FILE:
#TEMPCAL:applied
#SENSITIVITY:applied
#LABORATORY:
#OPERATOR:Alberto
#REMARK:
#SAMPLE:PHBH_microspheres
#SAMPLE MASS /mg:8
#MATERIAL:
#REFERENCE:vuoto
#REFERENCE MASS /mg:0
#TYPE OF CRUCIBLE:Concavus Pan Al, pierced lid
#SAMPLE CRUCIBLE MASS /mg:0
#REFERENCE CRUCIBLE MASS /mg:0
#M.RANGE /�V:5000
#TAU-R:applied
#CORR. CODE:050
#EXO:+1
#RANGE:25�C/10,0(K/min)/180�C
#SEGMENT:S1/5
#SEG. 1:25�C/10,0(K/min)/180�C

#Temp./C;Time/min;DSC/(mW/mg);Sensit./(uV/mW)
 25.15105; 0.00000;-2.704494e-002;3.46667
 25.65105; 0.13033;      -0.31996;3.46700
 26.15105; 0.18320;      -0.32840;3.46732
 26.65105; 0.22366;      -0.32868;3.46764
 27.15105; 0.25951;      -0.32575;3.46796
 27.65105; 0.29358;      -0.32065;3.46827
 28.15105; 0.32744;      -0.31506;3.46857
 28.65105; 0.36228;      -0.30897;3.46887
 29.15105; 0.39921;      -0.30312;3.46917
 29.65105; 0.43946;      -0.29898;3.46946
 30.15105; 0.48443;      -0.29442;3.46974
 30.65105; 0.53516;      -0.28357;3.47002
 31.15105; 0.59137;      -0.27815;3.47029
 31.65105; 0.65046;      -0.26447;3.47056
 32.15105; 0.70880;      -0.26410;3.47083
 32.65105; 0.76428;      -0.26903;3.47109
 33.15105; 0.81677;      -0.27892;3.47134
 33.65105; 0.86693;      -0.28926;3.47159
 34.15105; 0.91557;      -0.29771;3.47184
 34.65105; 0.96345;      -0.30342;3.47208
 35.15105; 1.01122;      -0.30643;3.47231
 35.65105; 1.05933;      -0.30668;3.47254
 36.15105; 1.10808;      -0.30453;3.47277
 36.65105; 1.15759;      -0.30156;3.47299
 37.15105; 1.20785;      -0.29855;3.47320
 37.65105; 1.25858;      -0.29641;3.47341
 38.15105; 1.30950;      -0.29567;3.47362
 38.65105; 1.36041;      -0.29615;3.47382
 39.15105; 1.41109;      -0.29749;3.47401
 39.65105; 1.46148;      -0.29958;3.47420
 40.15105; 1.51151;      -0.30157;3.47439
 40.65105; 1.56133;      -0.30287;3.47457
 41.15105; 1.61105;      -0.30369;3.47474
 41.65105; 1.66080;      -0.30433;3.47491
 42.15105; 1.71071;      -0.30484;3.47508
 42.65105; 1.76076;      -0.30525;3.47524
 43.15105; 1.81091;      -0.30577;3.47540
 43.65105; 1.86111;      -0.30634;3.47555
 44.15105; 1.91131;      -0.30701;3.47569
 44.65105; 1.96148;      -0.30770;3.47584
 45.15105; 2.01158;      -0.30831;3.47597
 45.65105; 2.06166;      -0.30885;3.47610
 46.15105; 2.11172;      -0.30940;3.47623
 46.65105; 2.16172;      -0.30997;3.47635
 47.15105; 2.21174;      -0.31057;3.47647
 47.65105; 2.26176;      -0.31114;3.47658
 48.15105; 2.31181;      -0.31156;3.47669
 48.65105; 2.36187;      -0.31201;3.47679
 49.15105; 2.41199;      -0.31247;3.47689
 49.65105; 2.46212;      -0.31310;3.47698
 50.15105; 2.51232;      -0.31398;3.47707
 50.65105; 2.56253;      -0.31505;3.47715
 51.15105; 2.61266;      -0.31643;3.47723
 51.65105; 2.66274;      -0.31787;3.47730
 52.15105; 2.71273;      -0.31938;3.47737
 52.65105; 2.76264;      -0.32094;3.47743
 53.15105; 2.81258;      -0.32249;3.47749
 53.65105; 2.86256;      -0.32424;3.47755
 54.15105; 2.91257;      -0.32613;3.47759
 54.65105; 2.96268;      -0.32817;3.47764
 55.15105; 3.01283;      -0.33034;3.47768
 55.65105; 3.06305;      -0.33258;3.47771
 56.15105; 3.11331;      -0.33495;3.47774
 56.65105; 3.16358;      -0.33746;3.47777
 57.15105; 3.21386;      -0.34006;3.47779
 57.65105; 3.26408;      -0.34286;3.47780
 58.15105; 3.31422;      -0.34558;3.47782
 58.65105; 3.36427;      -0.34820;3.47782
 59.15105; 3.41423;      -0.35060;3.47782
 59.65105; 3.46416;      -0.35255;3.47782
 60.15105; 3.51408;      -0.35421;3.47781
 60.65105; 3.56409;      -0.35568;3.47780
 61.15105; 3.61421;      -0.35697;3.47778
 61.65105; 3.66440;      -0.35831;3.47776
 62.15105; 3.71464;      -0.35967;3.47773
 62.65105; 3.76488;      -0.36089;3.47770
 63.15105; 3.81501;      -0.36210;3.47766
 63.65105; 3.86509;      -0.36307;3.47762
 64.15105; 3.91510;      -0.36393;3.47758
 64.65105; 3.96510;      -0.36472;3.47753
 65.15105; 4.01513;      -0.36538;3.47747
 65.65105; 4.06518;      -0.36602;3.47741
 66.15105; 4.11522;      -0.36665;3.47735
 66.65105; 4.16527;      -0.36718;3.47728
 67.15105; 4.21529;      -0.36763;3.47721
 67.65105; 4.26528;      -0.36802;3.47713
 68.15105; 4.31533;      -0.36831;3.47704
 68.65105; 4.36538;      -0.36864;3.47696
 69.15105; 4.41545;      -0.36914;3.47686
 69.65105; 4.46552;      -0.36966;3.47677
 70.15105; 4.51553;      -0.37024;3.47667
 70.65105; 4.56548;      -0.37079;3.47656
 71.15105; 4.61542;      -0.37120;3.47645
 71.65105; 4.66534;      -0.37161;3.47633
 72.15105; 4.71529;      -0.37190;3.47621
 72.65105; 4.76530;      -0.37216;3.47609
 73.15105; 4.81538;      -0.37243;3.47596
 73.65105; 4.86548;      -0.37257;3.47582
 74.15105; 4.91558;      -0.37276;3.47569
 74.65105; 4.96566;      -0.37283;3.47554
 75.15105; 5.01571;      -0.37285;3.47540
 75.65105; 5.06576;      -0.37292;3.47524
 76.15105; 5.11579;      -0.37303;3.47509
 76.65105; 5.16581;      -0.37323;3.47493
 77.15105; 5.21583;      -0.37339;3.47476
 77.65105; 5.26588;      -0.37361;3.47459
 78.15105; 5.31597;      -0.37403;3.47442
 78.65105; 5.36604;      -0.37459;3.47424
 79.15105; 5.41607;      -0.37532;3.47405
 79.65105; 5.46605;      -0.37612;3.47386
 80.15105; 5.51600;      -0.37689;3.47367
 80.65105; 5.56591;      -0.37771;3.47347
 81.15105; 5.61585;      -0.37846;3.47327
 81.65105; 5.66577;      -0.37911;3.47307
 82.15105; 5.71576;      -0.37976;3.47286
 82.65105; 5.76586;      -0.38041;3.47264
 83.15105; 5.81601;      -0.38120;3.47242
 83.65105; 5.86619;      -0.38228;3.47220
 84.15105; 5.91634;      -0.38348;3.47197
 84.65105; 5.96643;      -0.38471;3.47174
 85.15105; 6.01645;      -0.38597;3.47150
 85.65105; 6.06646;      -0.38716;3.47126
 86.15105; 6.11646;      -0.38824;3.47101
 86.65105; 6.16648;      -0.38937;3.47076
 87.15105; 6.21654;      -0.39051;3.47050
 87.65105; 6.26665;      -0.39165;3.47024
 88.15105; 6.31679;      -0.39294;3.46998
 88.65105; 6.36694;      -0.39426;3.46971
 89.15105; 6.41706;      -0.39556;3.46944
 89.65105; 6.46713;      -0.39689;3.46916
 90.15105; 6.51719;      -0.39824;3.46888
 90.65105; 6.56727;      -0.39964;3.46860
 91.15105; 6.61735;      -0.40115;3.46831
 91.65105; 6.66743;      -0.40275;3.46801
 92.15105; 6.71747;      -0.40439;3.46771
 92.65105; 6.76749;      -0.40619;3.46741
 93.15105; 6.81751;      -0.40790;3.46710
 93.65105; 6.86746;      -0.40954;3.46679
 94.15105; 6.91744;      -0.41112;3.46647
 94.65105; 6.96750;      -0.41262;3.46615
 95.15105; 7.01762;      -0.41420;3.46583
 95.65105; 7.06783;      -0.41595;3.46550
 96.15105; 7.11805;      -0.41782;3.46517
 96.65105; 7.16825;      -0.41995;3.46483
 97.15105; 7.21839;      -0.42213;3.46449
 97.65105; 7.26848;      -0.42438;3.46414
 98.15105; 7.31854;      -0.42676;3.46379
 98.65105; 7.36866;      -0.42894;3.46343
 99.15105; 7.41871;      -0.43116;3.46308
 99.65105; 7.46882;      -0.43344;3.46271
100.15105; 7.51904;      -0.43578;3.46235
100.65105; 7.56926;      -0.43836;3.46197
101.15105; 7.61947;      -0.44109;3.46160
101.65105; 7.66965;      -0.44388;3.46122
102.15105; 7.71976;      -0.44665;3.46083
102.65105; 7.76986;      -0.44947;3.46044
103.15105; 7.81997;      -0.45246;3.46005
103.65105; 7.87009;      -0.45552;3.45966
104.15105; 7.92021;      -0.45868;3.45925
104.65105; 7.97033;      -0.46189;3.45885
105.15105; 8.02045;      -0.46506;3.45844
105.65105; 8.07052;      -0.46810;3.45803
106.15105; 8.12060;      -0.47114;3.45761
106.65105; 8.17071;      -0.47410;3.45719
107.15105; 8.22092;      -0.47705;3.45676
107.65105; 8.27123;      -0.48021;3.45633
108.15105; 8.32165;      -0.48361;3.45590
108.65105; 8.37204;      -0.48739;3.45546
109.15105; 8.42239;      -0.49166;3.45502
109.65105; 8.47263;      -0.49613;3.45457
110.15105; 8.52281;      -0.50077;3.45412
110.65105; 8.57296;      -0.50544;3.45366
111.15105; 8.62307;      -0.51005;3.45321
111.65105; 8.67319;      -0.51463;3.45274
112.15105; 8.72332;      -0.51907;3.45228
112.65105; 8.77349;      -0.52352;3.45180
113.15105; 8.82370;      -0.52801;3.45133
113.65105; 8.87396;      -0.53270;3.45085
114.15105; 8.92420;      -0.53745;3.45037
114.65105; 8.97448;      -0.54223;3.44988
115.15105; 9.02475;      -0.54700;3.44939
115.65105; 9.07503;      -0.55175;3.44889
116.15105; 9.12534;      -0.55654;3.44840
116.65105; 9.17576;      -0.56116;3.44789
117.15105; 9.22620;      -0.56574;3.44739
117.65105; 9.27665;      -0.57073;3.44687
118.15105; 9.32703;      -0.57622;3.44636
118.65105; 9.37727;      -0.58291;3.44584
119.15105; 9.42746;      -0.59001;3.44532
119.65105; 9.47756;      -0.59708;3.44479
120.15105; 9.52772;      -0.60338;3.44426
120.65105; 9.57798;      -0.60878;3.44373
121.15105; 9.62833;      -0.61352;3.44319
121.65105; 9.67877;      -0.61848;3.44264
122.15105; 9.72924;      -0.62349;3.44210
122.65105; 9.77969;      -0.62899;3.44155
123.15105; 9.83007;      -0.63478;3.44099
123.65105; 9.88042;      -0.64063;3.44044
124.15105; 9.93073;      -0.64616;3.43987
124.65105; 9.98096;      -0.65127;3.43931
125.15105;10.03118;      -0.65541;3.43874
125.65105;10.08127;      -0.65775;3.43816
126.15105;10.13128;      -0.65737;3.43759
126.65105;10.18120;      -0.65422;3.43701
127.15105;10.23095;      -0.64697;3.43642
127.65105;10.28053;      -0.63657;3.43583
128.15105;10.32994;      -0.62213;3.43524
128.65105;10.37918;      -0.60405;3.43464
129.15105;10.42826;      -0.58336;3.43404
129.65105;10.47725;      -0.56096;3.43344
130.15105;10.52617;      -0.53814;3.43283
130.65105;10.57506;      -0.51655;3.43222
131.15105;10.62396;      -0.49682;3.43160
131.65105;10.67292;      -0.47986;3.43098
132.15105;10.72196;      -0.46479;3.43036
132.65105;10.77118;      -0.45213;3.42973
133.15105;10.82055;      -0.44117;3.42910
133.65105;10.87001;      -0.43191;3.42847
134.15105;10.91956;      -0.42449;3.42783
134.65105;10.96911;      -0.41865;3.42719
135.15105;11.01871;      -0.41333;3.42654
135.65105;11.06831;      -0.40813;3.42590
136.15105;11.11790;      -0.40289;3.42524
136.65105;11.16751;      -0.39761;3.42459
137.15105;11.21710;      -0.39096;3.42393
137.65105;11.26671;      -0.38492;3.42326
138.15105;11.31638;      -0.37881;3.42259
138.65105;11.36612;      -0.37266;3.42192
139.15105;11.41592;      -0.36731;3.42125
139.65105;11.46575;      -0.36328;3.42057
140.15105;11.51564;      -0.36011;3.41989
140.65105;11.56554;      -0.35743;3.41920
141.15105;11.61542;      -0.35608;3.41851
141.65105;11.66536;      -0.35459;3.41782
142.15105;11.71530;      -0.35342;3.41713
142.65105;11.76524;      -0.35270;3.41643
143.15105;11.81525;      -0.35222;3.41572
143.65105;11.86522;      -0.35193;3.41502
144.15105;11.91518;      -0.35169;3.41430
144.65105;11.96518;      -0.35174;3.41359
145.15105;12.01508;      -0.35216;3.41287
145.65105;12.06491;      -0.35238;3.41215
146.15105;12.11478;      -0.35209;3.41143
146.65105;12.16461;      -0.35154;3.41070
147.15105;12.21458;      -0.35096;3.40997
147.65105;12.26466;      -0.35060;3.40923
148.15105;12.31481;      -0.35047;3.40849
148.65105;12.36500;      -0.35050;3.40775
149.15105;12.41515;      -0.35072;3.40700
149.65105;12.46521;      -0.35109;3.40626
150.15105;12.51526;      -0.35148;3.40550
150.65105;12.56522;      -0.35180;3.40475
151.15105;12.61514;      -0.35195;3.40399
151.65105;12.66509;      -0.35205;3.40322
152.15105;12.71506;      -0.35206;3.40246
152.65105;12.76505;      -0.35220;3.40169
153.15105;12.81509;      -0.35241;3.40092
153.65105;12.86511;      -0.35258;3.40014
154.15105;12.91510;      -0.35278;3.39936
154.65105;12.96512;      -0.35296;3.39858
155.15105;13.01513;      -0.35312;3.39779
155.65105;13.06511;      -0.35327;3.39700
156.15105;13.11510;      -0.35344;3.39620
156.65105;13.16511;      -0.35360;3.39541
157.15105;13.21511;      -0.35368;3.39461
157.65105;13.26510;      -0.35380;3.39380
158.15105;13.31511;      -0.35387;3.39300
158.65105;13.36513;      -0.35381;3.39219
159.15105;13.41516;      -0.35368;3.39137
159.65105;13.46527;      -0.35332;3.39056
160.15105;13.51541;      -0.35292;3.38974
160.65105;13.56570;      -0.35268;3.38891
161.15105;13.61609;      -0.35302;3.38809
161.65105;13.66641;      -0.35399;3.38726
162.15105;13.71661;      -0.35532;3.38642
162.65105;13.76658;      -0.35665;3.38559
163.15105;13.81635;      -0.35764;3.38475
163.65105;13.86593;      -0.35817;3.38391
164.15105;13.91543;      -0.35829;3.38306
164.65105;13.96500;      -0.35794;3.38221
165.15105;14.01468;      -0.35742;3.38136
165.65105;14.06446;      -0.35687;3.38050
166.15105;14.11441;      -0.35644;3.37964
166.65105;14.16451;      -0.35618;3.37878
167.15105;14.21467;      -0.35613;3.37792
167.65105;14.26489;      -0.35614;3.37705
168.15105;14.31510;      -0.35627;3.37618
168.65105;14.36528;      -0.35647;3.37530
169.15105;14.41544;      -0.35682;3.37442
169.65105;14.46558;      -0.35727;3.37354
170.15105;14.51562;      -0.35774;3.37266
170.65105;14.56562;      -0.35810;3.37177
171.15105;14.61560;      -0.35826;3.37088
171.65105;14.66555;      -0.35832;3.36999
172.15105;14.71554;      -0.35844;3.36909
172.65105;14.76555;      -0.35855;3.36819
173.15105;14.81556;      -0.35871;3.36729
173.65105;14.86557;      -0.35892;3.36638
174.15105;14.91555;      -0.35907;3.36547
174.65105;14.96551;      -0.35919;3.36456
175.15105;15.01546;      -0.35937;3.36365
175.65105;15.06545;      -0.35934;3.36273
176.15105;15.11545;      -0.35928;3.36181
176.65105;15.16548;      -0.35925;3.36088
177.15105;15.21555;      -0.35923;3.35996
177.65105;15.26563;      -0.35942;3.35903
178.15105;15.31569;      -0.35974;3.35809
178.65105;15.36571;      -0.36019;3.35716
179.15105;15.41569;      -0.36058;3.35622
179.65105;15.46560;      -0.36081;3.35528