File: Latex/Final_thesis_document/Raw_Data/DSC/DSC_Alberto/Normal/ExpDat_PHBH-first cooling.txt
#EXPORTTYPE:DATA SINGLE
#FILE:PHBH.ngb-sdg
#FORMAT:NETZSCH5
#FTYPE:ASCII
#IDENTITY:PHBH
#DECIMAL:POINT
#SEPARATOR:SEMICOLON
#MTYPE:DSC
#INSTRUMENT:NETZSCH DSC 214
#PROJECT:
#DATE/TIME:22.09.2021 15:49
#CORR. FILE:
#TEMPCAL:applied
#SENSITIVITY:applied
#LABORATORY:
#OPERATOR:Alberto
#REMARK:
#SAMPLE:PHBH
#SAMPLE MASS /mg:6.4
#MATERIAL:
#REFERENCE:vuoto
#REFERENCE MASS /mg:0
#TYPE OF CRUCIBLE:Concavus Pan Al, pierced lid
#SAMPLE CRUCIBLE MASS /mg:0
#REFERENCE CRUCIBLE MASS /mg:0
#M.RANGE /‘V:5000
#TAU-R:applied
#CORR. CODE:050
#EXO:+1
#RANGE:180›C/10,0(K/min)/-30›C
#SEGMENT:S3/5
#SEG. 3:180›C/10,0(K/min)/-30›C

##Temp./›C;Time/min;DSC/(mW/mg);Sensit./(uV/mW)
-30.07011;39.49583;0.19462;3.39859
-29.07011;39.39596;0.19681;3.40038
-28.07011;39.29613;0.19831;3.40216
-27.07011;39.19617;0.19934;3.40392
-26.07011;39.09615;0.20043;3.40565
-25.07011;38.99627;0.20157;3.40736
-24.07011;38.89636;0.20270;3.40906
-23.07011;38.79638;0.20396;3.41073
-22.07011;38.69647;0.20542;3.41238
-21.07011;38.59658;0.20694;3.41401
-20.07011;38.49679;0.20845;3.41562
-19.07011;38.39700;0.21004;3.41721
-18.07011;38.29693;0.21157;3.41877
-17.07011;38.19686;0.21345;3.42032
-16.07011;38.09702;0.21594;3.42184
-15.07011;37.99728;0.21809;3.42335
-14.07011;37.89751;0.22031;3.42483
-13.07011;37.79774;0.22294;3.42629
-12.07011;37.69784;0.22523;3.42774
-11.07011;37.59787;0.22899;3.42916
-10.07011;37.49806;0.23290;3.43056
 -9.07011;37.39831;0.23696;3.43194
 -8.07011;37.29854;0.24148;3.43329
 -7.07011;37.19885;0.24772;3.43463
 -6.07011;37.09934;0.25352;3.43595
 -5.07011;36.99974;0.26001;3.43724
 -4.07011;36.89994;0.26746;3.43852
 -3.07011;36.80002;0.27606;3.43977
 -2.07011;36.70027;0.28450;3.44101
 -1.07011;36.60060;0.29288;3.44222
 -0.07011;36.50099;0.30023;3.44341
  0.92989;36.40132;0.30583;3.44458
  1.92989;36.30153;0.31017;3.44573
  2.92989;36.20169;0.31362;3.44686
  3.92989;36.10185;0.31601;3.44797
  4.92989;36.00198;0.31765;3.44906
  5.92989;35.90195;0.31914;3.45013
  6.92989;35.80183;0.32059;3.45117
  7.92989;35.70175;0.32203;3.45220
  8.92989;35.60178;0.32359;3.45321
  9.92989;35.50198;0.32503;3.45419
 10.92989;35.40224;0.32611;3.45516
 11.92989;35.30233;0.32696;3.45610
 12.92989;35.20233;0.32788;3.45703
 13.92989;35.10226;0.32904;3.45793
 14.92989;35.00222;0.33048;3.45881
 15.92989;34.90234;0.33202;3.45967
 16.92989;34.80255;0.33346;3.46052
 17.92989;34.70273;0.33480;3.46134
 18.92989;34.60290;0.33608;3.46214
 19.92989;34.50291;0.33729;3.46292
 20.92989;34.40286;0.33875;3.46368
 21.92989;34.30291;0.34063;3.46442
 22.92989;34.20300;0.34256;3.46514
 23.92989;34.10304;0.34425;3.46584
 24.92989;34.00297;0.34674;3.46652
 25.92989;33.90303;0.34990;3.46718
 26.92989;33.80334;0.35312;3.46782
 27.92989;33.70381;0.35612;3.46844
 28.92989;33.60410;0.35866;3.46904
 29.92989;33.50410;0.36158;3.46961
 30.92989;33.40410;0.36610;3.47017
 31.92989;33.30433;0.37075;3.47071
 32.92989;33.20469;0.37475;3.47123
 33.92989;33.10498;0.37908;3.47173
 34.92989;33.00508;0.38329;3.47221
 35.92989;32.90520;0.38840;3.47267
 36.92989;32.80539;0.39323;3.47311
 37.92989;32.70565;0.39831;3.47353
 38.92989;32.60586;0.40304;3.47393
 39.92989;32.50592;0.40730;3.47431
 40.92989;32.40603;0.41244;3.47467
 41.92989;32.30630;0.41660;3.47501
 42.92989;32.20660;0.41989;3.47533
 43.92989;32.10668;0.42180;3.47563
 44.92989;32.00666;0.42353;3.47591
 45.92989;31.90672;0.42523;3.47617
 46.92989;31.80678;0.42556;3.47642
 47.92989;31.70674;0.42462;3.47664
 48.92989;31.60656;0.42279;3.47684
 49.92989;31.50632;0.42061;3.47703
 50.92989;31.40616;0.41816;3.47719
 51.92989;31.30610;0.41470;3.47734
 52.92989;31.20606;0.41072;3.47747
 53.92989;31.10614;0.40690;3.47757
 54.92989;31.00612;0.40213;3.47766
 55.92989;30.90582;0.39787;3.47773
 56.92989;30.80542;0.39602;3.47778
 57.92989;30.70524;0.39477;3.47781
 58.92989;30.60521;0.39378;3.47782
 59.92989;30.50520;0.39309;3.47782
 60.92989;30.40532;0.39251;3.47779
 61.92989;30.30540;0.39154;3.47774
 62.92989;30.20530;0.38992;3.47768
 63.92989;30.10508;0.38830;3.47760
 64.92989;30.00496;0.38681;3.47750
 65.92989;29.90502;0.38534;3.47738
 66.92989;29.80521;0.38272;3.47724
 67.92989;29.70518;0.37990;3.47708
 68.92989;29.60495;0.37835;3.47691
 69.92989;29.50478;0.37837;3.47671
 70.92989;29.40482;0.37860;3.47650
 71.92989;29.30487;0.37878;3.47627
 72.92989;29.20481;0.37878;3.47602
 73.92989;29.10475;0.37913;3.47575
 74.92989;29.00485;0.37999;3.47546
 75.92989;28.90506;0.38063;3.47516
 76.92989;28.80509;0.38080;3.47484
 77.92989;28.70493;0.38128;3.47449
 78.92989;28.60489;0.38238;3.47413
 79.92989;28.50519;0.38358;3.47376
 80.92989;28.40548;0.38387;3.47336
 81.92989;28.30533;0.38358;3.47295
 82.92989;28.20487;0.38429;3.47252
 83.92989;28.10463;0.38603;3.47207
 84.92989;28.00497;0.38833;3.47160
 85.92989;27.90575;0.38934;3.47112
 86.92989;27.80638;0.38889;3.47062
 87.92989;27.70638;0.38792;3.47010
 88.92989;27.60585;0.38756;3.46956
 89.92989;27.50531;0.38886;3.46901
 90.92989;27.40522;0.39077;3.46843
 91.92989;27.30535;0.39207;3.46785
 92.92989;27.20547;0.39280;3.46724
 93.92989;27.10556;0.39341;3.46661
 94.92989;27.00562;0.39389;3.46597
 95.92989;26.90558;0.39452;3.46531
 96.92989;26.80552;0.39534;3.46464
 97.92989;26.70548;0.39622;3.46395
 98.92989;26.60549;0.39710;3.46324
 99.92989;26.50542;0.39806;3.46251
100.92989;26.40552;0.40023;3.46176
101.92989;26.30623;0.40296;3.46100
102.92989;26.20730;0.40299;3.46023
103.92989;26.10776;0.39965;3.45943
104.92989;26.00701;0.39742;3.45862
105.92989;25.90605;0.39997;3.45779
106.92989;25.80569;0.40309;3.45695
107.92989;25.70576;0.40446;3.45609
108.92989;25.60600;0.40556;3.45521
109.92989;25.50633;0.40635;3.45432
110.92989;25.40661;0.40681;3.45341
111.92989;25.30680;0.40717;3.45248
112.92989;25.20682;0.40748;3.45154
113.92989;25.10665;0.40797;3.45058
114.92989;25.00657;0.40903;3.44961
115.92989;24.90660;0.41021;3.44862
116.92989;24.80658;0.41083;3.44761
117.92989;24.70655;0.41167;3.44659
118.92989;24.60672;0.41315;3.44555
119.92989;24.50704;0.41406;3.44450
120.92989;24.40715;0.41410;3.44343
121.92989;24.30704;0.41418;3.44234
122.92989;24.20689;0.41507;3.44124
123.92989;24.10685;0.41634;3.44012
124.92989;24.00692;0.41733;3.43899
125.92989;23.90714;0.41811;3.43784
126.92989;23.80734;0.41865;3.43668
127.92989;23.70731;0.41883;3.43550
128.92989;23.60705;0.41911;3.43431
129.92989;23.50676;0.42024;3.43310
130.92989;23.40690;0.42203;3.43187
131.92989;23.30735;0.42328;3.43064
132.92989;23.20774;0.42337;3.42938
133.92989;23.10771;0.42290;3.42811
134.92989;23.00739;0.42295;3.42683
135.92989;22.90709;0.42412;3.42553
136.92989;22.80717;0.42577;3.42422
137.92989;22.70750;0.42688;3.42289
138.92989;22.60781;0.42725;3.42155
139.92989;22.50790;0.42756;3.42019
140.92989;22.40780;0.42796;3.41882
141.92989;22.30769;0.42875;3.41743
142.92989;22.20771;0.42972;3.41603
143.92989;22.10775;0.43043;3.41462
144.92989;22.00774;0.43110;3.41319
145.92989;21.90770;0.43190;3.41175
146.92989;21.80761;0.43267;3.41029
147.92989;21.70754;0.43355;3.40882
148.92989;21.60765;0.43485;3.40734
149.92989;21.50789;0.43588;3.40584
150.92989;21.40803;0.43638;3.40432
151.92989;21.30805;0.43675;3.40280
152.92989;21.20784;0.43700;3.40126
153.92989;21.10751;0.43759;3.39970
154.92989;21.00739;0.43897;3.39814
155.92989;20.90754;0.44038;3.39656
156.92989;20.80775;0.44116;3.39496
157.92989;20.70788;0.44164;3.39335
158.92989;20.60792;0.44212;3.39173
159.92989;20.50790;0.44296;3.39010
160.92989;20.40793;0.44387;3.38845
161.92989;20.30800;0.44463;3.38679
162.92989;20.20820;0.44557;3.38512
163.92989;20.10854;0.44565;3.38343
164.92989;20.00862;0.44412;3.38173
165.92989;19.90791;0.44353;3.38002
166.92989;19.80651;0.44394;3.37830
167.92989;19.70550;0.45285;3.37656
168.92989;19.60641;0.46641;3.37481
169.92989;19.50953;0.47071;3.37305
170.92989;19.41300;0.45737;3.37127
171.92989;19.31263;0.42316;3.36949
172.92989;19.20345;0.39003;3.36769
173.92989;19.08787;0.42247;3.36588
174.92989;18.98469;0.53383;3.36405
175.92989;18.90091;0.63635;3.36222
176.92989;18.82865;0.66553;3.36037
177.92989;18.75890;0.59428;3.35851
178.92989;18.67842;0.37921;3.35663