File: Latex/Final_thesis_document/Raw_Data/DSC/DSC_Alberto/Normal/ExpDat_PHBH-first heating.txt
#EXPORTTYPE:DATA SINGLE
#FILE:PHBH.ngb-sdg
#FORMAT:NETZSCH5
#FTYPE:ASCII
#IDENTITY:PHBH
#DECIMAL:POINT
#SEPARATOR:SEMICOLON
#MTYPE:DSC
#INSTRUMENT:NETZSCH DSC 214
#PROJECT:
#DATE/TIME:22.09.2021 15:49
#CORR. FILE:
#TEMPCAL:applied
#SENSITIVITY:applied
#LABORATORY:
#OPERATOR:Alberto
#REMARK:
#SAMPLE:PHBH
#SAMPLE MASS /mg:6.4
#MATERIAL:
#REFERENCE:vuoto
#REFERENCE MASS /mg:0
#TYPE OF CRUCIBLE:Concavus Pan Al, pierced lid
#SAMPLE CRUCIBLE MASS /mg:0
#REFERENCE CRUCIBLE MASS /mg:0
#M.RANGE /‘V:5000
#TAU-R:applied
#CORR. CODE:050
#EXO:+1
#RANGE:25›C/10,0(K/min)/180›C
#SEGMENT:S1/5
#SEG. 1:25›C/10,0(K/min)/180›C

##Temp./›C;Time/min;DSC/(mW/mg);Sensit./(uV/mW)
 25.15901; 0.00000;-8.083194e-003;3.46667
 25.65901; 0.12834;      -0.33382;3.46700
 26.15901; 0.18069;      -0.34593;3.46733
 26.65901; 0.22088;      -0.34920;3.46765
 27.15901; 0.25664;      -0.34855;3.46796
 27.65901; 0.29072;      -0.34518;3.46827
 28.15901; 0.32468;      -0.34099;3.46858
 28.65901; 0.35973;      -0.33543;3.46888
 29.15901; 0.39700;      -0.32992;3.46917
 29.65901; 0.43772;      -0.32649;3.46946
 30.15901; 0.48325;      -0.32232;3.46974
 30.65901; 0.53459;      -0.31353;3.47002
 31.15901; 0.59117;      -0.30691;3.47030
 31.65901; 0.65020;      -0.29746;3.47057
 32.15901; 0.70813;      -0.29792;3.47083
 32.65901; 0.76312;      -0.30181;3.47109
 33.15901; 0.81515;      -0.30816;3.47135
 33.65901; 0.86502;      -0.31520;3.47160
 34.15901; 0.91346;      -0.32136;3.47184
 34.65901; 0.96128;      -0.32588;3.47208
 35.15901; 1.00909;      -0.32848;3.47232
 35.65901; 1.05736;      -0.32915;3.47255
 36.15901; 1.10633;      -0.32839;3.47277
 36.65901; 1.15602;      -0.32684;3.47299
 37.15901; 1.20631;      -0.32520;3.47321
 37.65901; 1.25702;      -0.32396;3.47342
 38.15901; 1.30792;      -0.32340;3.47362
 38.65901; 1.35878;      -0.32358;3.47382
 39.15901; 1.40943;      -0.32452;3.47402
 39.65901; 1.45981;      -0.32594;3.47421
 40.15901; 1.50993;      -0.32736;3.47439
 40.65901; 1.55984;      -0.32883;3.47457
 41.15901; 1.60967;      -0.32995;3.47475
 41.65901; 1.65948;      -0.33099;3.47492
 42.15901; 1.70937;      -0.33183;3.47508
 42.65901; 1.75929;      -0.33258;3.47524
 43.15901; 1.80929;      -0.33339;3.47540
 43.65901; 1.85938;      -0.33408;3.47555
 44.15901; 1.90952;      -0.33489;3.47570
 44.65901; 1.95970;      -0.33593;3.47584
 45.15901; 2.00995;      -0.33713;3.47597
 45.65901; 2.06019;      -0.33864;3.47610
 46.15901; 2.11041;      -0.34035;3.47623
 46.65901; 2.16053;      -0.34235;3.47635
 47.15901; 2.21052;      -0.34449;3.47647
 47.65901; 2.26040;      -0.34671;3.47658
 48.15901; 2.31020;      -0.34903;3.47669
 48.65901; 2.36005;      -0.35121;3.47679
 49.15901; 2.41001;      -0.35356;3.47689
 49.65901; 2.46007;      -0.35591;3.47698
 50.15901; 2.51031;      -0.35830;3.47707
 50.65901; 2.56062;      -0.36111;3.47715
 51.15901; 2.61103;      -0.36396;3.47723
 51.65901; 2.66145;      -0.36719;3.47730
 52.15901; 2.71186;      -0.37085;3.47737
 52.65901; 2.76224;      -0.37466;3.47743
 53.15901; 2.81243;      -0.37864;3.47749
 53.65901; 2.86256;      -0.38260;3.47755
 54.15901; 2.91257;      -0.38643;3.47760
 54.65901; 2.96256;      -0.39011;3.47764
 55.15901; 3.01256;      -0.39364;3.47768
 55.65901; 3.06254;      -0.39703;3.47771
 56.15901; 3.11256;      -0.40013;3.47774
 56.65901; 3.16262;      -0.40282;3.47777
 57.15901; 3.21268;      -0.40525;3.47779
 57.65901; 3.26283;      -0.40741;3.47780
 58.15901; 3.31303;      -0.40933;3.47782
 58.65901; 3.36330;      -0.41104;3.47782
 59.15901; 3.41354;      -0.41269;3.47782
 59.65901; 3.46377;      -0.41414;3.47782
 60.15901; 3.51393;      -0.41549;3.47781
 60.65901; 3.56400;      -0.41662;3.47780
 61.15901; 3.61401;      -0.41755;3.47778
 61.65901; 3.66398;      -0.41816;3.47776
 62.15901; 3.71396;      -0.41849;3.47773
 62.65901; 3.76400;      -0.41859;3.47770
 63.15901; 3.81409;      -0.41856;3.47766
 63.65901; 3.86420;      -0.41855;3.47762
 64.15901; 3.91434;      -0.41856;3.47758
 64.65901; 3.96443;      -0.41868;3.47753
 65.15901; 4.01444;      -0.41889;3.47747
 65.65901; 4.06443;      -0.41915;3.47741
 66.15901; 4.11429;      -0.41941;3.47735
 66.65901; 4.16408;      -0.41961;3.47728
 67.15901; 4.21387;      -0.41972;3.47720
 67.65901; 4.26361;      -0.41979;3.47713
 68.15901; 4.31343;      -0.41975;3.47704
 68.65901; 4.36327;      -0.41966;3.47695
 69.15901; 4.41316;      -0.41955;3.47686
 69.65901; 4.46317;      -0.41943;3.47677
 70.15901; 4.51322;      -0.41937;3.47666
 70.65901; 4.56338;      -0.41927;3.47656
 71.15901; 4.61361;      -0.41933;3.47645
 71.65901; 4.66386;      -0.41960;3.47633
 72.15901; 4.71408;      -0.42009;3.47621
 72.65901; 4.76429;      -0.42070;3.47609
 73.15901; 4.81444;      -0.42149;3.47596
 73.65901; 4.86454;      -0.42250;3.47582
 74.15901; 4.91460;      -0.42371;3.47568
 74.65901; 4.96458;      -0.42503;3.47554
 75.15901; 5.01447;      -0.42634;3.47539
 75.65901; 5.06430;      -0.42755;3.47524
 76.15901; 5.11412;      -0.42864;3.47509
 76.65901; 5.16395;      -0.42963;3.47492
 77.15901; 5.21391;      -0.43042;3.47476
 77.65901; 5.26392;      -0.43113;3.47459
 78.15901; 5.31398;      -0.43183;3.47441
 78.65901; 5.36409;      -0.43259;3.47423
 79.15901; 5.41421;      -0.43351;3.47405
 79.65901; 5.46441;      -0.43458;3.47386
 80.15901; 5.51466;      -0.43584;3.47367
 80.65901; 5.56493;      -0.43724;3.47347
 81.15901; 5.61517;      -0.43887;3.47327
 81.65901; 5.66530;      -0.44067;3.47306
 82.15901; 5.71532;      -0.44239;3.47285
 82.65901; 5.76526;      -0.44418;3.47264
 83.15901; 5.81517;      -0.44577;3.47242
 83.65901; 5.86512;      -0.44731;3.47219
 84.15901; 5.91510;      -0.44881;3.47197
 84.65901; 5.96517;      -0.45016;3.47173
 85.15901; 6.01527;      -0.45169;3.47149
 85.65901; 6.06543;      -0.45313;3.47125
 86.15901; 6.11559;      -0.45462;3.47101
 86.65901; 6.16568;      -0.45620;3.47076
 87.15901; 6.21577;      -0.45774;3.47050
 87.65901; 6.26581;      -0.45930;3.47024
 88.15901; 6.31582;      -0.46081;3.46998
 88.65901; 6.36584;      -0.46223;3.46971
 89.15901; 6.41587;      -0.46358;3.46944
 89.65901; 6.46589;      -0.46483;3.46916
 90.15901; 6.51594;      -0.46614;3.46888
 90.65901; 6.56599;      -0.46741;3.46859
 91.15901; 6.61606;      -0.46878;3.46830
 91.65901; 6.66614;      -0.47020;3.46801
 92.15901; 6.71623;      -0.47156;3.46771
 92.65901; 6.76630;      -0.47297;3.46740
 93.15901; 6.81639;      -0.47436;3.46710
 93.65901; 6.86649;      -0.47581;3.46678
 94.15901; 6.91660;      -0.47745;3.46647
 94.65901; 6.96673;      -0.47926;3.46615
 95.15901; 7.01685;      -0.48117;3.46582
 95.65901; 7.06694;      -0.48324;3.46549
 96.15901; 7.11700;      -0.48541;3.46516
 96.65901; 7.16704;      -0.48768;3.46482
 97.15901; 7.21704;      -0.48998;3.46448
 97.65901; 7.26706;      -0.49234;3.46413
 98.15901; 7.31713;      -0.49477;3.46378
 98.65901; 7.36726;      -0.49722;3.46343
 99.15901; 7.41742;      -0.49988;3.46307
 99.65901; 7.46759;      -0.50271;3.46271
100.15901; 7.51774;      -0.50565;3.46234
100.65901; 7.56782;      -0.50886;3.46197
101.15901; 7.61785;      -0.51211;3.46159
101.65901; 7.66785;      -0.51527;3.46121
102.15901; 7.71784;      -0.51844;3.46083
102.65901; 7.76788;      -0.52153;3.46044
103.15901; 7.81799;      -0.52457;3.46005
103.65901; 7.86819;      -0.52767;3.45965
104.15901; 7.91843;      -0.53091;3.45925
104.65901; 7.96877;      -0.53426;3.45884
105.15901; 8.01908;      -0.53792;3.45843
105.65901; 8.06939;      -0.54176;3.45802
106.15901; 8.11970;      -0.54566;3.45760
106.65901; 8.16998;      -0.54989;3.45718
107.15901; 8.22030;      -0.55427;3.45675
107.65901; 8.27065;      -0.55921;3.45632
108.15901; 8.32100;      -0.56468;3.45589
108.65901; 8.37128;      -0.57020;3.45545
109.15901; 8.42141;      -0.57800;3.45501
109.65901; 8.47144;      -0.58753;3.45456
110.15901; 8.52143;      -0.59735;3.45411
110.65901; 8.57145;      -0.60737;3.45366
111.15901; 8.62160;      -0.61708;3.45320
111.65901; 8.67188;      -0.62414;3.45274
112.15901; 8.72222;      -0.62917;3.45227
112.65901; 8.77254;      -0.63202;3.45180
113.15901; 8.82278;      -0.63115;3.45132
113.65901; 8.87291;      -0.62799;3.45084
114.15901; 8.92292;      -0.62185;3.45036
114.65901; 8.97278;      -0.61345;3.44987
115.15901; 9.02262;      -0.60416;3.44938
115.65901; 9.07234;      -0.59290;3.44889
116.15901; 9.12202;      -0.58208;3.44839
116.65901; 9.17167;      -0.57313;3.44788
117.15901; 9.22125;      -0.56418;3.44738
117.65901; 9.27091;      -0.55834;3.44687
118.15901; 9.32058;      -0.55379;3.44635
118.65901; 9.37028;      -0.55214;3.44583
119.15901; 9.42005;      -0.55309;3.44531
119.65901; 9.46992;      -0.55657;3.44478
120.15901; 9.51987;      -0.56134;3.44425
120.65901; 9.56995;      -0.56785;3.44372
121.15901; 9.62023;      -0.57549;3.44318
121.65901; 9.67060;      -0.58439;3.44264
122.15901; 9.72104;      -0.59403;3.44209
122.65901; 9.77153;      -0.60619;3.44154
123.15901; 9.82206;      -0.61782;3.44098
123.65901; 9.87264;      -0.62992;3.44043
124.15901; 9.92326;      -0.64219;3.43986
124.65901; 9.97392;      -0.65481;3.43930
125.15901;10.02457;      -0.66628;3.43873
125.65901;10.07515;      -0.67839;3.43815
126.15901;10.12567;      -0.68953;3.43758
126.65901;10.17611;      -0.70060;3.43700
127.15901;10.22649;      -0.70956;3.43641
127.65901;10.27682;      -0.71757;3.43582
128.15901;10.32713;      -0.72414;3.43523
128.65901;10.37737;      -0.72804;3.43463
129.15901;10.42754;      -0.72993;3.43403
129.65901;10.47760;      -0.73005;3.43343
130.15901;10.52754;      -0.72600;3.43282
130.65901;10.57737;      -0.71982;3.43221
131.15901;10.62712;      -0.70779;3.43159
131.65901;10.67672;      -0.69154;3.43097
132.15901;10.72615;      -0.67152;3.43035
132.65901;10.77535;      -0.64681;3.42972
133.15901;10.82429;      -0.61903;3.42909
133.65901;10.87302;      -0.58822;3.42846
134.15901;10.92163;      -0.55672;3.42782
134.65901;10.97020;      -0.52571;3.42718
135.15901;11.01891;      -0.49887;3.42653
135.65901;11.06779;      -0.47545;3.42588
136.15901;11.11691;      -0.45726;3.42523
136.65901;11.16620;      -0.44270;3.42458
137.15901;11.21564;      -0.43291;3.42391
137.65901;11.26516;      -0.42580;3.42325
138.15901;11.31479;      -0.42147;3.42258
138.65901;11.36457;      -0.41796;3.42191
139.15901;11.41448;      -0.41506;3.42124
139.65901;11.46442;      -0.41251;3.42056
140.15901;11.51435;      -0.41113;3.41988
140.65901;11.56429;      -0.41097;3.41919
141.15901;11.61416;      -0.41046;3.41850
141.65901;11.66404;      -0.40998;3.41781
142.15901;11.71397;      -0.40950;3.41711
142.65901;11.76390;      -0.40900;3.41641
143.15901;11.81380;      -0.40874;3.41571
143.65901;11.86376;      -0.40846;3.41500
144.15901;11.91374;      -0.40821;3.41429
144.65901;11.96378;      -0.40820;3.41358
145.15901;12.01388;      -0.40882;3.41286
145.65901;12.06403;      -0.41023;3.41214
146.15901;12.11420;      -0.41220;3.41141
146.65901;12.16433;      -0.41420;3.41069
147.15901;12.21447;      -0.41581;3.40996
147.65901;12.26452;      -0.41693;3.40922
148.15901;12.31448;      -0.41751;3.40848
148.65901;12.36445;      -0.41740;3.40774
149.15901;12.41441;      -0.41694;3.40699
149.65901;12.46443;      -0.41591;3.40624
150.15901;12.51446;      -0.41472;3.40549
150.65901;12.56453;      -0.41334;3.40473
151.15901;12.61456;      -0.41212;3.40398
151.65901;12.66455;      -0.41100;3.40321
152.15901;12.71447;      -0.41026;3.40245
152.65901;12.76435;      -0.40956;3.40168
153.15901;12.81414;      -0.40898;3.40090
153.65901;12.86396;      -0.40824;3.40013
154.15901;12.91376;      -0.40740;3.39935
154.65901;12.96359;      -0.40657;3.39856
155.15901;13.01351;      -0.40565;3.39778
155.65901;13.06353;      -0.40481;3.39699
156.15901;13.11367;      -0.40419;3.39619
156.65901;13.16383;      -0.40396;3.39540
157.15901;13.21393;      -0.40402;3.39459
157.65901;13.26398;      -0.40417;3.39379
158.15901;13.31399;      -0.40428;3.39298
158.65901;13.36396;      -0.40429;3.39217
159.15901;13.41396;      -0.40445;3.39136
159.65901;13.46398;      -0.40460;3.39054
160.15901;13.51400;      -0.40482;3.38972
160.65901;13.56405;      -0.40494;3.38890
161.15901;13.61406;      -0.40509;3.38807
161.65901;13.66407;      -0.40521;3.38724
162.15901;13.71407;      -0.40534;3.38641
162.65901;13.76401;      -0.40555;3.38557
163.15901;13.81394;      -0.40570;3.38473
163.65901;13.86384;      -0.40584;3.38389
164.15901;13.91374;      -0.40583;3.38305
164.65901;13.96370;      -0.40570;3.38220
165.15901;14.01371;      -0.40553;3.38134
165.65901;14.06375;      -0.40538;3.38049
166.15901;14.11383;      -0.40524;3.37963
166.65901;14.16390;      -0.40517;3.37877
167.15901;14.21396;      -0.40516;3.37790
167.65901;14.26405;      -0.40522;3.37703
168.15901;14.31414;      -0.40538;3.37616
168.65901;14.36421;      -0.40576;3.37529
169.15901;14.41424;      -0.40624;3.37441
169.65901;14.46422;      -0.40657;3.37353
170.15901;14.51414;      -0.40690;3.37264
170.65901;14.56403;      -0.40697;3.37176
171.15901;14.61393;      -0.40694;3.37087
171.65901;14.66387;      -0.40664;3.36997
172.15901;14.71391;      -0.40622;3.36908
172.65901;14.76408;      -0.40589;3.36818
173.15901;14.81429;      -0.40592;3.36727
173.65901;14.86452;      -0.40631;3.36637
174.15901;14.91467;      -0.40696;3.36546
174.65901;14.96466;      -0.40767;3.36455
175.15901;15.01453;      -0.40823;3.36363
175.65901;15.06434;      -0.40849;3.36271
176.15901;15.11416;      -0.40852;3.36179
176.65901;15.16405;      -0.40847;3.36087
177.15901;15.21398;      -0.40828;3.35994
177.65901;15.26398;      -0.40809;3.35901
178.15901;15.31402;      -0.40790;3.35808
178.65901;15.36407;      -0.40792;3.35714
179.15901;15.41413;      -0.40810;3.35620
179.65901;15.46423;      -0.40825;3.35526