File: Latex/Final_thesis_document/Raw_Data/DSC/DSC_Alberto/Normal/ExpDat_PHBH-second heating.txt
#EXPORTTYPE:DATA SINGLE
#FILE:PHBH.ngb-sdg
#FORMAT:NETZSCH5
#FTYPE:ASCII
#IDENTITY:PHBH
#DECIMAL:POINT
#SEPARATOR:SEMICOLON
#MTYPE:DSC
#INSTRUMENT:NETZSCH DSC 214
#PROJECT:
#DATE/TIME:22.09.2021 15:49
#CORR. FILE:
#TEMPCAL:applied
#SENSITIVITY:applied
#LABORATORY:
#OPERATOR:Alberto
#REMARK:
#SAMPLE:PHBH
#SAMPLE MASS /mg:6.4
#MATERIAL:
#REFERENCE:vuoto
#REFERENCE MASS /mg:0
#TYPE OF CRUCIBLE:Concavus Pan Al, pierced lid
#SAMPLE CRUCIBLE MASS /mg:0
#REFERENCE CRUCIBLE MASS /mg:0
#M.RANGE /‘V:5000
#TAU-R:applied
#CORR. CODE:050
#EXO:+1
#RANGE:-30›C/10,0(K/min)/180›C
#SEGMENT:S5/5
#SEG. 5:-30›C/10,0(K/min)/180›C

##Temp./›C;Time/min;DSC/(mW/mg);Sensit./(uV/mW)
-29.83753;42.50583;-1.928130e-002;3.39901
-28.83753;42.68329;      -0.27685;3.40080
-27.83753;42.75791;      -0.27085;3.40257
-26.83753;42.82494;      -0.26063;3.40432
-25.83753;42.89705;      -0.25132;3.40605
-24.83753;42.98477;      -0.24505;3.40776
-23.83753;43.09552;      -0.23370;3.40945
-22.83753;43.21206;      -0.23452;3.41111
-21.83753;43.31711;      -0.24588;3.41276
-20.83753;43.41436;      -0.25298;3.41439
-19.83753;43.51001;      -0.25354;3.41599
-18.83753;43.60784;      -0.25106;3.41757
-17.83753;43.70842;      -0.24934;3.41913
-16.83753;43.81007;      -0.24971;3.42068
-15.83753;43.91111;      -0.25156;3.42220
-14.83753;44.01129;      -0.25334;3.42370
-13.83753;44.11102;      -0.25453;3.42517
-12.83753;44.21079;      -0.25549;3.42663
-11.83753;44.31076;      -0.25616;3.42807
-10.83753;44.41095;      -0.25705;3.42948
 -9.83753;44.51125;      -0.25862;3.43088
 -8.83753;44.61142;      -0.26044;3.43225
 -7.83753;44.71143;      -0.26254;3.43361
 -6.83753;44.81149;      -0.26500;3.43494
 -5.83753;44.91157;      -0.26806;3.43625
 -4.83753;45.01176;      -0.27230;3.43754
 -3.83753;45.11204;      -0.27816;3.43881
 -2.83753;45.21231;      -0.28563;3.44006
 -1.83753;45.31264;      -0.29681;3.44129
 -0.83753;45.41338;      -0.31295;3.44250
  0.16247;45.51455;      -0.33570;3.44369
  1.16247;45.61580;      -0.36447;3.44485
  2.16247;45.71674;      -0.38541;3.44600
  3.16247;45.81694;      -0.38378;3.44712
  4.16247;45.91650;      -0.37052;3.44823
  5.16247;46.01604;      -0.36193;3.44931
  6.16247;46.11587;      -0.35806;3.45037
  7.16247;46.21594;      -0.35667;3.45141
  8.16247;46.31605;      -0.35640;3.45244
  9.16247;46.41605;      -0.35659;3.45344
 10.16247;46.51600;      -0.35661;3.45442
 11.16247;46.61588;      -0.35642;3.45538
 12.16247;46.71596;      -0.35621;3.45632
 13.16247;46.81615;      -0.35637;3.45724
 14.16247;46.91619;      -0.35679;3.45814
 15.16247;47.01605;      -0.35687;3.45901
 16.16247;47.11595;      -0.35651;3.45987
 17.16247;47.21595;      -0.35570;3.46071
 18.16247;47.31605;      -0.35501;3.46153
 19.16247;47.41620;      -0.35468;3.46232
 20.16247;47.51619;      -0.35419;3.46310
 21.16247;47.61603;      -0.35313;3.46385
 22.16247;47.71590;      -0.35175;3.46459
 23.16247;47.81588;      -0.35036;3.46530
 24.16247;47.91584;      -0.34905;3.46600
 25.16247;48.01580;      -0.34782;3.46667
 26.16247;48.11583;      -0.34689;3.46733
 27.16247;48.21597;      -0.34648;3.46796
 28.16247;48.31598;      -0.34620;3.46858
 29.16247;48.41584;      -0.34557;3.46917
 30.16247;48.51575;      -0.34468;3.46975
 31.16247;48.61577;      -0.34329;3.47030
 32.16247;48.71583;      -0.34138;3.47083
 33.16247;48.81582;      -0.33940;3.47135
 34.16247;48.91568;      -0.33666;3.47184
 35.16247;49.01555;      -0.33278;3.47232
 36.16247;49.11547;      -0.32814;3.47277
 37.16247;49.21530;      -0.32197;3.47321
 38.16247;49.31501;      -0.31406;3.47362
 39.16247;49.41472;      -0.30350;3.47402
 40.16247;49.51419;      -0.28629;3.47439
 41.16247;49.61335;      -0.26099;3.47475
 42.16247;49.71204;      -0.22286;3.47508
 43.16247;49.81008;      -0.16479;3.47540
 44.16247;49.90718;-8.782988e-002;3.47570
 45.16247;50.00318; 1.210602e-002;3.47597
 46.16247;50.09839;       0.12263;3.47623
 47.16247;50.19389;       0.21550;3.47647
 48.16247;50.29121;       0.24661;3.47669
 49.16247;50.39178;       0.18834;3.47689
 50.16247;50.49563; 7.695128e-002;3.47707
 51.16247;50.60047;-3.422461e-002;3.47723
 52.16247;50.70447;      -0.11916;3.47737
 53.16247;50.80749;      -0.17781;3.47749
 54.16247;50.90971;      -0.21922;3.47760
 55.16247;51.01124;      -0.24855;3.47768
 56.16247;51.11232;      -0.27020;3.47774
 57.16247;51.21332;      -0.28258;3.47779
 58.16247;51.31409;      -0.29486;3.47782
 59.16247;51.41435;      -0.30481;3.47782
 60.16247;51.51428;      -0.31165;3.47781
 61.16247;51.61433;      -0.31647;3.47778
 62.16247;51.71464;      -0.32066;3.47773
 63.16247;51.81507;      -0.32506;3.47766
 64.16247;51.91538;      -0.32918;3.47758
 65.16247;52.01552;      -0.33306;3.47747
 66.16247;52.11565;      -0.33692;3.47735
 67.16247;52.21568;      -0.34039;3.47720
 68.16247;52.31569;      -0.34328;3.47704
 69.16247;52.41594;      -0.34599;3.47686
 70.16247;52.51636;      -0.34930;3.47666
 71.16247;52.61675;      -0.35311;3.47645
 72.16247;52.71679;      -0.35705;3.47621
 73.16247;52.81662;      -0.36038;3.47596
 74.16247;52.91656;      -0.36334;3.47568
 75.16247;53.01685;      -0.36665;3.47539
 76.16247;53.11721;      -0.37040;3.47508
 77.16247;53.21731;      -0.37428;3.47476
 78.16247;53.31745;      -0.37784;3.47441
 79.16247;53.41771;      -0.38186;3.47405
 80.16247;53.51795;      -0.38608;3.47367
 81.16247;53.61809;      -0.39042;3.47327
 82.16247;53.71816;      -0.39482;3.47285
 83.16247;53.81819;      -0.40003;3.47242
 84.16247;53.91841;      -0.40494;3.47196
 85.16247;54.01880;      -0.40912;3.47149
 86.16247;54.11906;      -0.41351;3.47100
 87.16247;54.21944;      -0.41846;3.47050
 88.16247;54.31967;      -0.42426;3.46997
 89.16247;54.41980;      -0.43046;3.46943
 90.16247;54.51999;      -0.43614;3.46888
 91.16247;54.62037;      -0.44150;3.46830
 92.16247;54.72057;      -0.44649;3.46771
 93.16247;54.82086;      -0.45066;3.46709
 94.16247;54.92078;      -0.45581;3.46647
 95.16247;55.02042;      -0.45902;3.46582
 96.16247;55.12041;      -0.45803;3.46516
 97.16247;55.22070;      -0.45685;3.46448
 98.16247;55.32140;      -0.45868;3.46378
 99.16247;55.42198;      -0.46623;3.46307
100.16247;55.52217;      -0.47654;3.46234
101.16247;55.62254;      -0.48269;3.46159
102.16247;55.72251;      -0.49350;3.46082
103.16247;55.82273;      -0.50152;3.46004
104.16247;55.92266;      -0.51304;3.45925
105.16247;56.02324;      -0.52965;3.45843
106.16247;56.12434;      -0.54734;3.45760
107.16247;56.22566;      -0.56157;3.45675
108.16247;56.32623;      -0.56610;3.45589
109.16247;56.42571;      -0.54952;3.45501
110.16247;56.52447;      -0.51876;3.45411
111.16247;56.62316;      -0.48708;3.45319
112.16247;56.72215;      -0.46590;3.45227
113.16247;56.82160;      -0.46132;3.45132
114.16247;56.92135;      -0.46956;3.45036
115.16247;57.02159;      -0.48497;3.44938
116.16247;57.12245;      -0.50365;3.44838
117.16247;57.22375;      -0.52548;3.44737
118.16247;57.32506;      -0.55433;3.44635
119.16247;57.42616;      -0.58402;3.44531
120.16247;57.52729;      -0.61244;3.44425
121.16247;57.62847;      -0.63749;3.44317
122.16247;57.72948;      -0.66154;3.44209
123.16247;57.83034;      -0.68534;3.44098
124.16247;57.93126;      -0.70436;3.43986
125.16247;58.03221;      -0.71951;3.43872
126.16247;58.13296;      -0.73077;3.43757
127.16247;58.23344;      -0.73635;3.43641
128.16247;58.33350;      -0.73742;3.43522
129.16247;58.43317;      -0.72971;3.43403
130.16247;58.53253;      -0.71225;3.43282
131.16247;58.63154;      -0.68696;3.43159
132.16247;58.73038;      -0.65195;3.43035
133.16247;58.82897;      -0.61148;3.42909
134.16247;58.92730;      -0.56864;3.42782
135.16247;59.02558;      -0.52430;3.42653
136.16247;59.12388;      -0.48495;3.42523
137.16247;59.22234;      -0.45403;3.42391
138.16247;59.32105;      -0.43270;3.42258
139.16247;59.42001;      -0.41941;3.42123
140.16247;59.51925;      -0.41047;3.41987
141.16247;59.61896;      -0.40521;3.41850
142.16247;59.71910;      -0.40169;3.41711
143.16247;59.81927;      -0.40159;3.41571
144.16247;59.91924;      -0.40137;3.41429
145.16247;60.01927;      -0.40156;3.41286
146.16247;60.11927;      -0.40239;3.41141
147.16247;60.21902;      -0.40261;3.40995
148.16247;60.31878;      -0.40221;3.40848
149.16247;60.41883;      -0.40174;3.40699
150.16247;60.51901;      -0.40173;3.40549
151.16247;60.61916;      -0.40205;3.40397
152.16247;60.71922;      -0.40263;3.40244
153.16247;60.81923;      -0.40317;3.40090
154.16247;60.91923;      -0.40340;3.39934
155.16247;61.01922;      -0.40413;3.39777
156.16247;61.11902;      -0.40470;3.39619
157.16247;61.21881;      -0.40411;3.39459
158.16247;61.31890;      -0.40359;3.39298
159.16247;61.41923;      -0.40363;3.39136
160.16247;61.51952;      -0.40404;3.38972
161.16247;61.61961;      -0.40480;3.38807
162.16247;61.71955;      -0.40562;3.38641
163.16247;61.81938;      -0.40590;3.38473
164.16247;61.91933;      -0.40561;3.38304
165.16247;62.01946;      -0.40569;3.38134
166.16247;62.11953;      -0.40592;3.37962
167.16247;62.21967;      -0.40582;3.37790
168.16247;62.31990;      -0.40630;3.37616
169.16247;62.42001;      -0.40745;3.37440
170.16247;62.51978;      -0.40872;3.37264
171.16247;62.61939;      -0.40920;3.37086
172.16247;62.71916;      -0.40872;3.36907
173.16247;62.81918;      -0.40839;3.36727
174.16247;62.91930;      -0.40869;3.36545
175.16247;63.01932;      -0.40874;3.36363
176.16247;63.11946;      -0.40866;3.36179
177.16247;63.21971;      -0.40905;3.35994
178.16247;63.31988;      -0.40958;3.35807
179.16247;63.42005;      -0.41038;3.35620